Workbook

Sheet Classes Charts
Q6: Take Aways
Q7: 1 | R7: There are large data gaps or extreme inconsistencies in scheduling
Q8: 2 | R8: Negative months don't make sense
Q9: 3 | R9: There are several instances of positive and negative cancelling transactions
S13: Search | T13: 92
S14: L1 | T14: 30
S15: L2 | T15: 45
S16: L3 | T16: 70
S17: L4 | T17: 25

Sheet Classes Chart Data
A1: Total Class Registration Count | L1: All Classes Revenue | X1: All Classes YTD Revenue | AK1: All Classes Quarterly Revenue
B2: 2023 | C2: 2024 | D2: 2025 | E2: 2026 | M2: 2023 | N2: 2024 | O2: 2025 | P2: 2026 | Q2: Target/Projection | Y2: 2024 YTD | Z2: 2025 YTD | AA2: 2026 YTD | AB2: Target | AC2: Stretch | AL2: 2023 | AM2: 2024 | AN2: 2025 | AO2: 2026
A3: Jan | B3: =B21+B39+B57+B75 -> 31 | C3: =C21+C39+C57+C75 -> 19 | D3: =D21+D39+D57+D75 -> 12 | E3: =E21+E39+E57+E75+E93 -> 119 | L3: Jan | M3: =M21+M39+M57+M75 -> 9401 | N3: =N21+N39+N57+N75 -> 5253.5 | O3: =O21+O39+O57+O75 -> 2763.5 | P3: =P21+P39+P57+P75 -> 8164.5 | Q3: 5253.5 | X3: Jan | Y3: ='Classes Data'!V15 -> 5348.5 | Z3: ='Classes Data'!V27 -> 2763.5 | AA3: ='Classes Data'!V39 -> 16730.5 | AB3: =(Z3*0.25)+Z3 -> 3454.375 | AC3: =(Z3*0.4)+Z3 -> 3868.9 | AK3: Q1 | AL3: =SUM(M3:M5) -> 21291 | AM3: =SUM(N3:N5) -> 15456 | AN3: =SUM(O3:O5) -> 12994 | AO3: =SUM(P3:P5) -> 8164.5
A4: Feb | B4: =B22+B40+B58+B76 -> 10 | C4: =C22+C40+C58+C76 -> 15 | D4: =D22+D40+D58+D76 -> 14 | E4: =E22+E40+E58+E76 -> 0 | L4: Feb | M4: =M22+M40+M58+M76 -> 2765 | N4: =N22+N40+N58+N76 -> 4147.5 | O4: =O22+O40+O58+O76 -> 3871 | P4: =P22+P40+P58+P76 -> 0 | Q4: 4147.5 | X4: Feb | Y4: =Y3+'Classes Data'!V16 -> 9496 | Z4: =Z3+'Classes Data'!V28 -> 6989.5 | AB4: =(Z4*0.25)+Z4 -> 8736.875 | AC4: =(Z4*0.4)+Z4 -> 9785.3 | AK4: Q2 | AL4: =SUM(M6:M8) -> 10683.5 | AM4: =SUM(N6:N8) -> 23502.5 | AN4: =SUM(O6:O8) -> 8017 | AO4: =SUM(P6:P8) -> 0
A5: Mar | B5: =B23+B41+B59+B77 -> 33 | C5: =C23+C41+C59+C77 -> 20 | D5: =D23+D41+D59+D77 -> 23 | E5: =E23+E41+E59+E77 -> 0 | L5: Mar | M5: =M23+M41+M59+M77 -> 9125 | N5: =N23+N41+N59+N77 -> 6055 | O5: =O23+O41+O59+O77 -> 6359.5 | P5: =P23+P41+P59+P77 -> 0 | Q5: 6055 | X5: Mar | Y5: =Y4+'Classes Data'!V17 -> 15891 | Z5: =Z4+'Classes Data'!V29 -> 13669 | AB5: =(Z5*0.25)+Z5 -> 17086.25 | AC5: =(Z5*0.4)+Z5 -> 19136.6 | AK5: Q3 | AL5: =SUM(M9:M11) -> 15204 | AM5: =SUM(N9:N11) -> 19346 | AN5: =SUM(O9:O11) -> 21009.5 | AO5: =SUM(P9:P11) -> 0
A6: Apr | B6: =B24+B42+B60+B78 -> 5 | C6: =C24+C42+C60+C78 -> 37 | D6: =D24+D42+D60+D78 -> 2 | E6: =E24+E42+E60+E78 -> 0 | L6: Apr | M6: =M24+M42+M60+M78 -> 1382.5 | N6: =N24+N42+N60+N78 -> 10230.5 | O6: =O24+O42+O60+O78 -> 551.5 | P6: =P24+P42+P60+P78 -> 0 | Q6: 10230.5 | X6: Apr | Y6: =Y5+'Classes Data'!V18 -> 26236.5 | Z6: =Z5+'Classes Data'!V30 -> 14410.5 | AB6: =(Z6*0.25)+Z6 -> 18013.125 | AC6: =(Z6*0.4)+Z6 -> 20174.7 | AK6: Q4 | AL6: =SUM(M12:M14) -> 15759 | AM6: =SUM(N12:N14) -> 13973.5 | AN6: =SUM(O12:O14) -> 16227 | AO6: =SUM(P12:P14) -> 0
A7: May | B7: =B25+B43+B61+B79 -> 26 | C7: =C25+C43+C61+C79 -> 14 | D7: =D25+D43+D61+D79 -> 15 | E7: =E25+E43+E61+E79 -> 0 | L7: May | M7: =M25+M43+M61+M79 -> 6812.5 | N7: =N25+N43+N61+N79 -> 3871 | O7: =O25+O43+O61+O79 -> 3871 | P7: =P25+P43+P61+P79 -> 0 | Q7: 3871 | X7: May | Y7: =Y6+'Classes Data'!V19 -> 30302.5 | Z7: =Z6+'Classes Data'!V31 -> 18281.5 | AB7: =(Z7*0.25)+Z7 -> 22851.875 | AC7: =(Z7*0.4)+Z7 -> 25594.1
A8: Jun | B8: =B26+B44+B62+B80 -> 12 | C8: =C26+C44+C62+C80 -> 27 | D8: =D26+D44+D62+D80 -> 13 | E8: =E26+E44+E62+E80 -> 0 | L8: Jun | M8: =M26+M44+M62+M80 -> 2488.5 | N8: =N26+N44+N62+N80 -> 9401 | O8: =O26+O44+O62+O80 -> 3594.5 | P8: =P26+P44+P62+P80 -> 0 | Q8: 9401 | X8: Jun | Y8: =Y7+'Classes Data'!V20 -> 40033.5 | Z8: =Z7+'Classes Data'!V32 -> 22086 | AB8: =(Z8*0.25)+Z8 -> 27607.5 | AC8: =(Z8*0.4)+Z8 -> 30920.4
A9: Jul | B9: =B27+B45+B63+B81 -> 18 | C9: =C27+C45+C63+C81 -> 13 | D9: =D27+D45+D63+D81 -> 36 | E9: =E27+E45+E63+E81 -> 0 | L9: Jul | M9: =M27+M45+M63+M81 -> 5253.5 | N9: =N27+N45+N63+N81 -> 3593 | O9: =O27+O45+O63+O81 -> 9677.5 | P9: =P27+P45+P63+P81 -> 0 | Q9: 3593 | X9: Jul | Y9: =Y8+'Classes Data'!V21 -> 43826.5 | Z9: =Z8+'Classes Data'!V33 -> 31838.5 | AB9: =(Z9*0.25)+Z9 -> 39798.125 | AC9: =(Z9*0.4)+Z9 -> 44573.9
A10: Aug | B10: =B28+B46+B64+B82 -> 19 | C10: =C28+C46+C64+C82 -> 40 | D10: =D28+D46+D64+D82 -> 16 | E10: =E28+E46+E64+E82 -> 0 | L10: Aug | M10: =M28+M46+M64+M82 -> 6081.5 | N10: =N28+N46+N64+N82 -> 11055.5 | O10: =O28+O46+O64+O82 -> 4422.5 | P10: =P28+P46+P64+P82 -> 0 | Q10: 11055.5 | X10: Aug | Y10: =Y9+'Classes Data'!V22 -> 55047 | Z10: =Z9+'Classes Data'!V34 -> 36396 | AB10: =(Z10*0.25)+Z10 -> 45495 | AC10: =(Z10*0.4)+Z10 -> 50954.4 | AK10: All Classes YoY Quarterly Revenue
A11: Sep | B11: =B29+B47+B65+B83 -> 15 | C11: =C29+C47+C65+C83 -> 17 | D11: =D29+D47+D65+D83 -> 25 | E11: =E29+E47+E65+E83 -> 0 | L11: Sep | M11: =M29+M47+M65+M83 -> 3869 | N11: =N29+N47+N65+N83 -> 4697.5 | O11: =O29+O47+O65+O83 -> 6909.5 | P11: =P29+P47+P65+P83 -> 0 | Q11: 4697.5 | X11: Sep | Y11: =Y10+'Classes Data'!V23 -> 60044.5 | Z11: =Z10+'Classes Data'!V35 -> 43470.5 | AB11: =(Z11*0.25)+Z11 -> 54338.125 | AC11: =(Z11*0.4)+Z11 -> 60858.7 | AL11: 2023 | AM11: 2024 | AN11: 2025 | AO11: 2026
A12: Oct | B12: =B30+B48+B66+B84 -> 20 | C12: =C30+C48+C66+C84 -> 0 | D12: =D30+D48+D66+D84 -> 17 | E12: =E30+E48+E66+E84 -> 0 | L12: Oct | M12: =M30+M48+M66+M84 -> 4977 | N12: =N30+N48+N66+N84 -> 0 | O12: =O30+O48+O66+O84 -> 4697.5 | P12: =P30+P48+P66+P84 -> 0 | Q12: 0 | X12: Oct | Y12: =Y11+'Classes Data'!V24 -> 60179.5 | Z12: =Z11+'Classes Data'!V36 -> 48663 | AB12: =(Z12*0.25)+Z12 -> 60828.75 | AC12: =(Z12*0.4)+Z12 -> 68128.2 | AK12: Q1 | AM12: =(AM3-AL3)/AL3 -> -0.27405946 | AN12: =(AN3-AM3)/AM3 -> -0.15929089 | AO12: =(AO3-AN3)/AN3 -> -0.37167154
A13: Nov | B13: =B31+B49+B67+B85 -> 12 | C13: =C31+C49+C67+C85 -> 22 | D13: =D31+D49+D67+D85 -> 18 | E13: =E31+E49+E67+E85 -> 0 | L13: Nov | M13: =M31+M49+M67+M85 -> 4147.5 | N13: =N31+N49+N67+N85 -> 6083 | O13: =O31+O49+O67+O85 -> 4610 | P13: =P31+P49+P67+P85 -> 0 | Q13: 6083 | X13: Nov | Y13: =Y12+'Classes Data'!V25 -> 66262.5 | Z13: =Z12+'Classes Data'!V37 -> 53458 | AB13: =(Z13*0.25)+Z13 -> 66822.5 | AC13: =(Z13*0.4)+Z13 -> 74841.2 | AK13: Q2 | AM13: =(AM4-AL4)/AL4 -> 1.1998877 | AN13: =(AN4-AM4)/AM4 -> -0.65888735
A14: Dec | B14: =B32+B50+B68+B86 -> 26 | C14: =C32+C50+C68+C86 -> 29 | D14: =D32+D50+D68+D86 -> 23 | E14: =E32+E50+E68+E86 -> 0 | L14: Dec | M14: =M32+M50+M68+M86 -> 6634.5 | N14: =N32+N50+N68+N86 -> 7890.5 | O14: =O32+O50+O68+O86 -> 6919.5 | P14: =P32+P50+P68+P86 -> 0 | Q14: 7890.5 | X14: Dec | Y14: =Y13+'Classes Data'!V26 -> 74153 | Z14: =Z13+'Classes Data'!V38 -> 61214 | AB14: =(Z14*0.25)+Z14 -> 76517.5 | AC14: =(Z14*0.4)+Z14 -> 85699.6 | AK14: Q3 | AM14: =(AM5-AL5)/AL5 -> 0.27242831 | AN14: =(AN5-AM5)/AM5 -> 0.085986767
Z15: =(Z14-Y14)/Y14 -> -0.17449058 | AK15: Q4 | AM15: =(AM6-AL6)/AL6 -> -0.11330034 | AN15: =(AN6-AM6)/AM6 -> 0.16126955
A19: Level 1 Registration Count | L19: Level 1 Revenue | X19: All Classes YTD MoM Revenue | AK19: All Classes Quarterly Registrations
B20: 2023 | C20: 2024 | D20: 2025 | E20: 2026 | M20: 2023 | N20: 2024 | O20: 2025 | P20: 2026 | Y20: 2024 YTD | Z20: 2025 YTD | AA20: 2026 YTD | AB20: Target | AL20: 2023 | AM20: 2024 | AN20: 2025 | AO20: 2026
A21: Jan | B21: ='Classes Data'!D3 -> 19 | C21: ='Classes Data'!D15 -> 17 | D21: 12 | E21: ='Classes Data'!D39 -> 14 | L21: Jan | M21: ='Classes Data'!E3 -> 5253.5 | N21: ='Classes Data'!E15 -> 4700.5 | O21: ='Classes Data'!E27 -> 3040 | P21: ='Classes Data'!E39 -> 4207.5 | X21: Jan | AB21: =AB39+AB57+AB75+AB93 -> 32.5 | AK21: Q1 | AL21: =SUM(B3:B5) -> 74 | AM21: =SUM(C3:C5) -> 54 | AN21: =SUM(D3:D5) -> 49 | AO21: =SUM(E3:E5) -> 119
A22: Feb | B22: ='Classes Data'!D4 -> 10 | C22: ='Classes Data'!D16 -> 11 | D22: ='Classes Data'!D28 -> 14 | E22: ='Classes Data'!D40 -> 0 | L22: Feb | M22: ='Classes Data'!E4 -> 2765 | N22: ='Classes Data'!E16 -> 3041.5 | O22: ='Classes Data'!E28 -> 3871 | P22: ='Classes Data'!E40 -> 0 | X22: Feb | Y22: =(Y4-Y3)/Y3 -> 0.77545106 | Z22: =(Z4-Z3)/Z3 -> 1.5292202 | AA22: =(AA4-AA3)/AA3 -> -1 | AB22: =AB40+AB58+AB76+AB94 -> 18130.75 | AK22: Q2 | AL22: =SUM(B6:B8) -> 43 | AM22: =SUM(C6:C8) -> 78 | AN22: =SUM(D6:D8) -> 30
A23: Mar | B23: ='Classes Data'!D5 -> 16 | C23: ='Classes Data'!D17 -> 9 | D23: ='Classes Data'!D29 -> 6 | E23: ='Classes Data'!D41 -> 0 | L23: Mar | M23: ='Classes Data'!E5 -> 4424 | N23: ='Classes Data'!E17 -> 3038.5 | O23: ='Classes Data'!E29 -> 1659 | P23: ='Classes Data'!E41 -> 0 | X23: Mar | Y23: =(Y5-Y4)/Y4 -> 0.67344145 | Z23: =(Z5-Z4)/Z4 -> 0.95564776 | AA23: =(AA5-AA4)/AA4 -> #DIV/0! | AB23: 18069.5 | AK23: Q3 | AL23: =SUM(B9:B11) -> 52 | AM23: =SUM(C9:C11) -> 70 | AN23: =SUM(D9:D11) -> 77
A24: Apr | B24: ='Classes Data'!D6 -> 8 | C24: ='Classes Data'!D18 -> 17 | D24: ='Classes Data'!D30 -> 4 | E24: ='Classes Data'!D42 -> 0 | L24: Apr | M24: ='Classes Data'!E6 -> 2212 | N24: ='Classes Data'!E18 -> 4700.5 | O24: ='Classes Data'!E30 -> 1106 | P24: ='Classes Data'!E42 -> 0 | X24: Apr | Y24: =(Y6-Y5)/Y5 -> 0.65102888 | Z24: =(Z6-Z5)/Z5 -> 0.054246836 | AA24: =(AA6-AA5)/AA5 -> #DIV/0! | AB24: 18069.5 | AK24: Q4 | AL24: =SUM(B12:B14) -> 58 | AM24: =SUM(C12:C14) -> 51 | AN24: =SUM(D12:D14) -> 58
A25: May | B25: ='Classes Data'!D7 -> 12 | C25: ='Classes Data'!D19 -> 14 | D25: ='Classes Data'!D31 -> 13 | E25: ='Classes Data'!D43 -> 0 | L25: May | M25: ='Classes Data'!E7 -> 3318 | N25: ='Classes Data'!E19 -> 3871 | O25: ='Classes Data'!E31 -> 3594.5 | P25: ='Classes Data'!E43 -> 0 | X25: May | Y25: =(Y7-Y6)/Y6 -> 0.15497494 | Z25: =(Z7-Z6)/Z6 -> 0.26862357 | AA25: =(AA7-AA6)/AA6 -> #DIV/0! | AB25: 18069.5
A26: Jun | B26: ='Classes Data'!D8 -> 8 | C26: ='Classes Data'!D20 -> 15 | D26: ='Classes Data'!D32 -> 6 | E26: ='Classes Data'!D44 -> 0 | F26: =((SUM(D21:D26)-SUM(C21:C26))/(SUM(C21:C26))) -> -0.3373494 | L26: Jun | M26: ='Classes Data'!E8 -> 2212 | N26: ='Classes Data'!E20 -> 4147.5 | O26: ='Classes Data'!E32 -> 1659 | P26: ='Classes Data'!E44 -> 0 | X26: Jun | Y26: =(Y8-Y7)/Y7 -> 0.32112862 | Z26: =(Z8-Z7)/Z7 -> 0.20810656 | AA26: =(AA8-AA7)/AA7 -> #DIV/0! | AB26: =AB25*2 -> 36139
A27: Jul | B27: ='Classes Data'!D9 -> 7 | C27: ='Classes Data'!D21 -> 9 | D27: ='Classes Data'!D33 -> 15 | E27: ='Classes Data'!D45 -> 0 | F27: =((SUM(D27:D30)-SUM(C27:C30))/(SUM(C27:C30))) -> 1 | L27: Jul | M27: ='Classes Data'!E9 -> 1935.5 | N27: ='Classes Data'!E21 -> 2488.5 | O27: ='Classes Data'!E33 -> 4147.5 | P27: ='Classes Data'!E45 -> 0 | X27: Jul | Y27: =(Y9-Y8)/Y8 -> 0.094745651 | Z27: =(Z9-Z8)/Z8 -> 0.44156932 | AA27: =(AA9-AA8)/AA8 -> #DIV/0! | AB27: =AB26 -> 36139
A28: Aug | B28: ='Classes Data'!D10 -> 15 | C28: ='Classes Data'!D22 -> 11 | D28: ='Classes Data'!D34 -> 13 | E28: ='Classes Data'!D46 -> 0 | L28: Aug | M28: ='Classes Data'!E10 -> 4146 | N28: ='Classes Data'!E22 -> 3041.5 | O28: ='Classes Data'!E34 -> 3594.5 | P28: ='Classes Data'!E46 -> 0 | X28: Aug | Y28: =(Y10-Y9)/Y9 -> 0.2560209 | Z28: =(Z10-Z9)/Z9 -> 0.14314431 | AA28: =(AA10-AA9)/AA9 -> #DIV/0! | AB28: =AB27 -> 36139 | AK28: All Classes YoY Quarterly Registrations
A29: Sep | B29: ='Classes Data'!D11 -> 11 | C29: ='Classes Data'!D23 -> 6 | D29: ='Classes Data'!D35 -> 13 | E29: ='Classes Data'!D47 -> 0 | L29: Sep | M29: ='Classes Data'!E11 -> 3040 | N29: ='Classes Data'!E23 -> 1659 | O29: ='Classes Data'!E35 -> 3593 | P29: ='Classes Data'!E47 -> 0 | X29: Sep | Y29: =(Y11-Y10)/Y10 -> 0.090786056 | Z29: =(Z11-Z10)/Z10 -> 0.19437576 | AA29: =(AA11-AA10)/AA10 -> #DIV/0! | AB29: =AB25*3 -> 54208.5 | AL29: 2023 | AM29: 2024 | AN29: 2025 | AO29: 2026
A30: Oct | B30: ='Classes Data'!D12 -> 9 | C30: ='Classes Data'!D24 -> 0 | D30: ='Classes Data'!D36 -> 11 | E30: ='Classes Data'!D48 -> 0 | L30: Oct | M30: ='Classes Data'!E12 -> 2488.5 | N30: ='Classes Data'!E24 -> 0 | O30: ='Classes Data'!E36 -> 3038.5 | P30: ='Classes Data'!E48 -> 0 | X30: Oct | Y30: =(Y12-Y11)/Y11 -> 0.0022483325 | Z30: =(Z12-Z11)/Z11 -> 0.11944882 | AA30: =(AA12-AA11)/AA11 -> #DIV/0! | AB30: =AB29 -> 54208.5 | AK30: Q1 | AM30: =(AM21-AL21)/AL21 -> -0.27027027 | AN30: =(AN21-AM21)/AM21 -> -0.092592593 | AO30: =(AO21-AN21)/AN21 -> 1.4285714
A31: Nov | B31: ='Classes Data'!D13 -> 9 | C31: ='Classes Data'!D25 -> 10 | D31: ='Classes Data'!D37 -> 9 | E31: ='Classes Data'!D49 -> 0 | L31: Nov | M31: ='Classes Data'!E13 -> 2488.5 | N31: ='Classes Data'!E25 -> 2765 | O31: ='Classes Data'!E37 -> 2284 | P31: ='Classes Data'!E49 -> 0 | X31: Nov | Y31: =(Y13-Y12)/Y12 -> 0.10108093 | AB31: =AB30 -> 54208.5 | AK31: Q2 | AM31: =(AM22-AL22)/AL22 -> 0.81395349 | AN31: =(AN22-AM22)/AM22 -> -0.61538462
A32: Dec | B32: ='Classes Data'!D14 -> 11 | C32: ='Classes Data'!D26 -> 12 | D32: ='Classes Data'!D38 -> 8 | E32: ='Classes Data'!D50 -> 0 | L32: Dec | M32: ='Classes Data'!E14 -> 3041.5 | N32: ='Classes Data'!E26 -> 3191.5 | O32: ='Classes Data'!E38 -> 2404 | P32: ='Classes Data'!E50 -> 0 | X32: Dec | Y32: =(Y14-Y13)/Y13 -> 0.11907942 | AB32: =Y32 -> 0.11907942 | AK32: Q3 | AM32: =(AM23-AL23)/AL23 -> 0.34615385 | AN32: =(AN23-AM23)/AM23 -> 0.1
AK33: Q4 | AM33: =(AM24-AL24)/AL24 -> -0.12068966 | AN33: =(AN24-AM24)/AM24 -> 0.1372549
X36: All Classes YTD Registrations
A37: Level 2 Registration Count | L37: Level 2 Revenue | Y37: 2024 YTD | Z37: 2025 YTD | AA37: 2026 YTD | AB37: Target | AC37: Stretch
B38: 2023 | C38: 2024 | D38: 2025 | E38: 2026 | M38: 2023 | N38: 2024 | O38: 2025 | P38: 2026 | X38: Jan | Y38: =C3 -> 19 | Z38: =D3 -> 12 | AA38: =E3 -> 119 | AB38: =(Z38*0.25)+Z38 -> 15 | AC38: =(Z38*0.4)+Z38 -> 16.8
A39: Jan | B39: ='Classes Data'!F3 -> 12 | C39: ='Classes Data'!F15 -> 0 | D39: ='Classes Data'!F27 -> -1 | E39: ='Classes Data'!F39 -> 13 | L39: Jan | M39: ='Classes Data'!G3 -> 3318 | N39: ='Classes Data'!G15 -> 0 | O39: ='Classes Data'!G27 -> -276.5 | P39: ='Classes Data'!G39 -> 3055.5 | X39: Feb | Y39: =Y38+C4 -> 34 | Z39: =Z38+D4 -> 26 | AA39: =E4 -> 0 | AB39: =(Z39*0.25)+Z39 -> 32.5 | AC39: =(Z39*0.4)+Z39 -> 36.4
A40: Feb | B40: ='Classes Data'!F4 -> 0 | C40: ='Classes Data'!F16 -> 0 | D40: ='Classes Data'!F28 -> 0 | E40: ='Classes Data'!F40 -> 0 | L40: Feb | M40: ='Classes Data'!G4 -> 0 | N40: ='Classes Data'!G16 -> 0 | O40: ='Classes Data'!G28 -> 0 | P40: ='Classes Data'!G40 -> 0 | X40: Mar | Y40: =Y39+C5 -> 54 | Z40: =Z39+D5 -> 49 | AA40: =E5 -> 0 | AB40: =(Z40*0.25)+Z40 -> 61.25 | AC40: =(Z40*0.4)+Z40 -> 68.6
A41: Mar | B41: ='Classes Data'!F5 -> 13 | C41: ='Classes Data'!F17 -> 11 | D41: ='Classes Data'!F29 -> 6 | E41: ='Classes Data'!F41 -> 0 | L41: Mar | M41: ='Classes Data'!G5 -> 3595 | N41: ='Classes Data'!G17 -> 3016.5 | O41: ='Classes Data'!G29 -> 1659 | P41: ='Classes Data'!G41 -> 0 | X41: Apr | Y41: =Y40+C6 -> 91 | Z41: =Z40+D6 -> 51 | AA41: =E6 -> 0 | AB41: =(Z41*0.25)+Z41 -> 63.75 | AC41: =(Z41*0.4)+Z41 -> 71.4
A42: Apr | B42: ='Classes Data'!F6 -> 0 | C42: ='Classes Data'!F18 -> 11 | D42: ='Classes Data'!F30 -> -3 | E42: ='Classes Data'!F42 -> 0 | L42: Apr | M42: ='Classes Data'!G6 -> 0 | N42: ='Classes Data'!G18 -> 3041.5 | O42: ='Classes Data'!G30 -> -829.5 | P42: ='Classes Data'!G42 -> 0 | X42: May | Y42: =Y41+C7 -> 105 | Z42: =Z41+D7 -> 66 | AA42: =E7 -> 0 | AB42: =(Z42*0.25)+Z42 -> 82.5 | AC42: =(Z42*0.4)+Z42 -> 92.4
A43: May | B43: ='Classes Data'!F7 -> 13 | C43: ='Classes Data'!F19 -> 0 | D43: ='Classes Data'!F31 -> 2 | E43: ='Classes Data'!F43 -> 0 | L43: May | M43: ='Classes Data'!G7 -> 3494.5 | N43: ='Classes Data'!G19 -> 0 | O43: ='Classes Data'!G31 -> 276.5 | P43: ='Classes Data'!G43 -> 0 | X43: Jun | Y43: =Y42+C8 -> 132 | Z43: =Z42+D8 -> 79 | AA43: =E8 -> 0 | AB43: =(Z43*0.25)+Z43 -> 98.75 | AC43: =(Z43*0.4)+Z43 -> 110.6
A44: Jun | B44: ='Classes Data'!F8 -> 0 | C44: ='Classes Data'!F20 -> 12 | D44: ='Classes Data'!F32 -> 7 | E44: ='Classes Data'!F44 -> 0 | L44: Jun | M44: ='Classes Data'!G8 -> 0 | N44: ='Classes Data'!G20 -> 3318 | O44: ='Classes Data'!G32 -> 1935.5 | P44: ='Classes Data'!G44 -> 0 | X44: Jul | Y44: =Y43+C9 -> 145 | Z44: =Z43+D9 -> 115 | AA44: =E9 -> 0 | AB44: =(Z44*0.25)+Z44 -> 143.75 | AC44: =(Z44*0.4)+Z44 -> 161
A45: Jul | B45: ='Classes Data'!F9 -> 8 | C45: ='Classes Data'!F21 -> 1 | D45: ='Classes Data'!F33 -> 8 | E45: ='Classes Data'!F45 -> 0 | L45: Jul | M45: ='Classes Data'!G9 -> 2212 | N45: ='Classes Data'!G21 -> 275 | O45: ='Classes Data'!G33 -> 2212 | P45: ='Classes Data'!G45 -> 0 | X45: Aug | Y45: =Y44+C10 -> 185 | Z45: =Z44+D10 -> 131 | AA45: =E10 -> 0 | AB45: =(Z45*0.25)+Z45 -> 163.75 | AC45: =(Z45*0.4)+Z45 -> 183.4
...

Sheet Sheet2
A1: All Classes Revenue
B2: 2023 | C2: 2024 | D2: 2025 | E2: 2026 | F2: Target/Projection
A3: Jan | B3: ='Classes Data'!V3 -> 9676 | C3: ='Classes Data'!V15 -> 5348.5 | D3: ='Classes Data'!V27 -> 2763.5 | E3: ='Classes Data'!V39 -> 16730.5 | F3: 5253.5

Sheet Classes Data
D1: Level 1 | F1: ='Raw Data'!E1 -> Level 2 | H1: ='Raw Data'!F1 -> Level 3 | J1: ='Raw Data'!G1 -> Level 4 | L1: Workshop | N1: ='Raw Data'!H1 -> HIS Showcase | P1: Long Form 1 | R1: Ross Byrant Workshop | T1: Manager Workshops | Y1: Month Over Month Change
A2: ='Raw Data'!A1 -> Date | B2: ='Raw Data'!B1 -> Month | C2: ='Raw Data'!C1 -> Year | D2: Tickets | E2: Revenue | F2: Tickets | G2: Revenue | H2: Tickets | I2: Revenue | J2: Tickets | K2: Revenue | L2: Tickets | M2: Revenue | N2: Tickets | O2: Revenue | P2: Tickets | Q2: Revenue | R2: Tickets | S2: Revenue | T2: Tickets | U2: Revenue | V2: Total | W2: Notes | Y2: Level 1 | Z2: Level 2 | AA2: Level 3 | AB2: Level 4 | AC2: HIS Showcase | AD2: Total
A3: ='Raw Data'!A2 -> 44927 | B3: ='Raw Data'!B2 -> Jan | C3: ='Raw Data'!C2 -> 2023 | D3: 19 | E3: ='Raw Data'!D2 -> 5253.5 | F3: 12 | G3: ='Raw Data'!E2 -> 3318 | H3: 3 | I3: ='Raw Data'!F2 -> 829.5 | K3: ='Raw Data'!G2 -> 0 | N3: 55 | O3: ='Raw Data'!H2 -> 275 | V3: =SUM(E3+G3+I3+K3+M3+O3) -> 9676
A4: ='Raw Data'!A3 -> 44958 | B4: ='Raw Data'!B3 -> Feb | C4: ='Raw Data'!C3 -> 2023 | D4: 10 | E4: ='Raw Data'!D3 -> 2765 | G4: ='Raw Data'!E3 -> 0 | I4: ='Raw Data'!F3 -> 0 | K4: ='Raw Data'!G3 -> 0 | O4: ='Raw Data'!H3 -> 0 | V4: =SUM(E4+G4+I4+K4+M4+O4) -> 2765 | Y4: =IFERROR((E4-E3)/E3,"") -> -0.47368421 | Z4: =IFERROR((G4-G3)/G3,"") -> -1 | AA4: =IFERROR((I4-I3)/I3,"") -> -1 | AB4: =IFERROR((K4-K3)/K3,"") | AC4: =IFERROR((O4-O3)/O3,"") -> -1 | AD4: =IFERROR((V4-V3)/V3,"") -> -0.71424142
A5: ='Raw Data'!A4 -> 44986 | B5: ='Raw Data'!B4 -> Mar | C5: ='Raw Data'!C4 -> 2023 | D5: 16 | E5: ='Raw Data'!D4 -> 4424 | F5: 13 | G5: ='Raw Data'!E4 -> 3595 | I5: ='Raw Data'!F4 -> 0 | J5: 4 | K5: ='Raw Data'!G4 -> 1106 | N5: 85 | O5: ='Raw Data'!H4 -> 425 | V5: =SUM(E5+G5+I5+K5+M5+O5) -> 9550 | Y5: =IFERROR((E5-E4)/E4,"") -> 0.6 | Z5: =IFERROR((G5-G4)/G4,"") | AA5: =IFERROR((I5-I4)/I4,"") | AB5: =IFERROR((K5-K4)/K4,"") | AC5: =IFERROR((O5-O4)/O4,"") | AD5: =IFERROR((V5-V4)/V4,"") -> 2.4538879
A6: ='Raw Data'!A5 -> 45017 | B6: ='Raw Data'!B5 -> Apr | C6: ='Raw Data'!C5 -> 2023 | D6: 8 | E6: ='Raw Data'!D5 -> 2212 | F6: 0 | G6: ='Raw Data'!E5 -> 0 | I6: ='Raw Data'!F5 -> 0 | J6: -3 | K6: ='Raw Data'!G5 -> -829.5 | N6: 22 | O6: ='Raw Data'!H5 -> 110 | V6: =SUM(E6+G6+I6+K6+M6+O6) -> 1492.5 | W6: L3 2 tick & 2 refunds | Y6: =IFERROR((E6-E5)/E5,"") -> -0.5 | Z6: =IFERROR((G6-G5)/G5,"") -> -1 | AA6: =IFERROR((I6-I5)/I5,"") | AB6: =IFERROR((K6-K5)/K5,"") -> -1.75 | AC6: =IFERROR((O6-O5)/O5,"") -> -0.74117647 | AD6: =IFERROR((V6-V5)/V5,"") -> -0.84371728
A7: ='Raw Data'!A6 -> 45047 | B7: ='Raw Data'!B6 -> May | C7: ='Raw Data'!C6 -> 2023 | D7: 12 | E7: ='Raw Data'!D6 -> 3318 | F7: 13 | G7: ='Raw Data'!E6 -> 3494.5 | I7: ='Raw Data'!F6 -> 0 | K7: ='Raw Data'!G6 -> 0 | N7: 50 | O7: ='Raw Data'!H6 -> 250 | V7: =SUM(E7+G7+I7+K7+M7+O7) -> 7062.5 | Y7: =IFERROR((E7-E6)/E6,"") -> 0.5 | Z7: =IFERROR((G7-G6)/G6,"") | AA7: =IFERROR((I7-I6)/I6,"") | AB7: =IFERROR((K7-K6)/K6,"") -> -1 | AC7: =IFERROR((O7-O6)/O6,"") -> 1.2727273 | AD7: =IFERROR((V7-V6)/V6,"") -> 3.7319933
A8: ='Raw Data'!A7 -> 45078 | B8: ='Raw Data'!B7 -> Jun | C8: ='Raw Data'!C7 -> 2023 | D8: 8 | E8: ='Raw Data'!D7 -> 2212 | G8: ='Raw Data'!E7 -> 0 | H8: 1 | I8: ='Raw Data'!F7 -> 276.5 | K8: ='Raw Data'!G7 -> 0 | N8: 14 | O8: ='Raw Data'!H7 -> 70 | V8: =SUM(E8+G8+I8+K8+M8+O8) -> 2558.5 | W8: L3 2 refunds | Y8: =IFERROR((E8-E7)/E7,"") -> -0.33333333 | Z8: =IFERROR((G8-G7)/G7,"") -> -1 | AA8: =IFERROR((I8-I7)/I7,"") | AB8: =IFERROR((K8-K7)/K7,"") | AC8: =IFERROR((O8-O7)/O7,"") -> -0.72 | AD8: =IFERROR((V8-V7)/V7,"") -> -0.63773451
A9: ='Raw Data'!A8 -> 45108 | B9: ='Raw Data'!B8 -> Jul | C9: ='Raw Data'!C8 -> 2023 | D9: 7 | E9: ='Raw Data'!D8 -> 1935.5 | F9: 8 | G9: ='Raw Data'!E8 -> 2212 | H9: 4 | I9: ='Raw Data'!F8 -> 1106 | K9: ='Raw Data'!G8 -> 0 | N9: 18 | O9: ='Raw Data'!H8 -> 90 | V9: =SUM(E9+G9+I9+K9+M9+O9) -> 5343.5 | Y9: =IFERROR((E9-E8)/E8,"") -> -0.125 | Z9: =IFERROR((G9-G8)/G8,"") | AA9: =IFERROR((I9-I8)/I8,"") -> 3 | AB9: =IFERROR((K9-K8)/K8,"") | AC9: =IFERROR((O9-O8)/O8,"") -> 0.28571429 | AD9: =IFERROR((V9-V8)/V8,"") -> 1.0885284
A10: ='Raw Data'!A9 -> 45139 | B10: ='Raw Data'!B9 -> Aug | C10: ='Raw Data'!C9 -> 2023 | D10: 15 | E10: ='Raw Data'!D9 -> 4146 | F10: 4 | G10: ='Raw Data'!E9 -> 1106 | H10: 3 | I10: ='Raw Data'!F9 -> 829.5 | K10: ='Raw Data'!G9 -> 0 | O10: ='Raw Data'!H9 -> 0 | V10: =SUM(E10+G10+I10+K10+M10+O10) -> 6081.5 | Y10: =IFERROR((E10-E9)/E9,"") -> 1.1420821 | Z10: =IFERROR((G10-G9)/G9,"") -> -0.5 | AA10: =IFERROR((I10-I9)/I9,"") -> -0.25 | AB10: =IFERROR((K10-K9)/K9,"") | AC10: =IFERROR((O10-O9)/O9,"") -> -1 | AD10: =IFERROR((V10-V9)/V9,"") -> 0.13811172
A11: ='Raw Data'!A10 -> 45170 | B11: ='Raw Data'!B10 -> Sep | C11: ='Raw Data'!C10 -> 2023 | D11: 11 | E11: ='Raw Data'!D10 -> 3040 | F11: 3 | G11: ='Raw Data'!E10 -> 829 | I11: ='Raw Data'!F10 -> 0 | K11: ='Raw Data'!G10 -> 0 | N11: 13 | O11: ='Raw Data'!H10 -> 65 | V11: =SUM(E11+G11+I11+K11+M11+O11) -> 3934 | Y11: =IFERROR((E11-E10)/E10,"") -> -0.26676315 | Z11: =IFERROR((G11-G10)/G10,"") -> -0.25045208 | AA11: =IFERROR((I11-I10)/I10,"") -> -1 | AB11: =IFERROR((K11-K10)/K10,"") | AC11: =IFERROR((O11-O10)/O10,"") | AD11: =IFERROR((V11-V10)/V10,"") -> -0.35312012
A12: ='Raw Data'!A11 -> 45200 | B12: ='Raw Data'!B11 -> Oct | C12: ='Raw Data'!C11 -> 2023 | D12: 9 | E12: ='Raw Data'!D11 -> 2488.5 | F12: 5 | G12: ='Raw Data'!E11 -> 1382.5 | H12: 1 | I12: ='Raw Data'!F11 -> 276.5 | J12: 3 | K12: ='Raw Data'!G11 -> 829.5 | N12: 63 | O12: ='Raw Data'!H11 -> 315 | V12: =SUM(E12+G12+I12+K12+M12+O12) -> 5292 | Y12: =IFERROR((E12-E11)/E11,"") -> -0.18141447 | Z12: =IFERROR((G12-G11)/G11,"") -> 0.66767189 | AA12: =IFERROR((I12-I11)/I11,"") | AB12: =IFERROR((K12-K11)/K11,"") | AC12: =IFERROR((O12-O11)/O11,"") -> 3.8461538 | AD12: =IFERROR((V12-V11)/V11,"") -> 0.34519573
A13: ='Raw Data'!A12 -> 45231 | B13: ='Raw Data'!B12 -> Nov | C13: ='Raw Data'!C12 -> 2023 | D13: 9 | E13: ='Raw Data'!D12 -> 2488.5 | G13: ='Raw Data'!E12 -> 0 | H13: 3 | I13: ='Raw Data'!F12 -> 829.5 | J13: 3 | K13: ='Raw Data'!G12 -> 829.5 | N13: 24 | O13: ='Raw Data'!H12 -> 120 | V13: =SUM(E13+G13+I13+K13+M13+O13) -> 4267.5 | Y13: =IFERROR((E13-E12)/E12,"") -> 0 | Z13: =IFERROR((G13-G12)/G12,"") -> -1 | AA13: =IFERROR((I13-I12)/I12,"") -> 2 | AB13: =IFERROR((K13-K12)/K12,"") -> 0 | AC13: =IFERROR((O13-O12)/O12,"") -> -0.61904762 | AD13: =IFERROR((V13-V12)/V12,"") -> -0.1935941
A14: ='Raw Data'!A13 -> 45261 | B14: ='Raw Data'!B13 -> Dec | C14: ='Raw Data'!C13 -> 2023 | D14: 11 | E14: ='Raw Data'!D13 -> 3041.5 | F14: 13 | G14: ='Raw Data'!E13 -> 3593 | I14: ='Raw Data'!F13 -> 0 | K14: ='Raw Data'!G13 -> 0 | N14: 21 | O14: ='Raw Data'!H13 -> 105 | V14: =SUM(E14+G14+I14+K14+M14+O14) -> 6739.5 | Y14: =IFERROR((E14-E13)/E13,"") -> 0.22222222 | Z14: =IFERROR((G14-G13)/G13,"") | AA14: =IFERROR((I14-I13)/I13,"") -> -1 | AB14: =IFERROR((K14-K13)/K13,"") -> -1 | AC14: =IFERROR((O14-O13)/O13,"") -> -0.125 | AD14: =IFERROR((V14-V13)/V13,"") -> 0.57926186
A15: ='Raw Data'!A14 -> 45292 | B15: ='Raw Data'!B14 -> Jan | C15: ='Raw Data'!C14 -> 2024 | D15: 17 | E15: ='Raw Data'!D14 -> 4700.5 | F15: 0 | G15: ='Raw Data'!E14 -> 0 | H15: 2 | I15: ='Raw Data'!F14 -> 553 | K15: ='Raw Data'!G14 -> 0 | N15: 19 | O15: ='Raw Data'!H14 -> 95 | V15: =SUM(E15+G15+I15+K15+M15+O15) -> 5348.5 | W15: L2 1 tic & 1 refund | Y15: =IFERROR((E15-E14)/E14,"") -> 0.54545455 | Z15: =IFERROR((G15-G14)/G14,"") -> -1 | AA15: =IFERROR((I15-I14)/I14,"") | AB15: =IFERROR((K15-K14)/K14,"") | AC15: =IFERROR((O15-O14)/O14,"") -> -0.095238095 | AD15: =IFERROR((V15-V14)/V14,"") -> -0.20639513
A16: ='Raw Data'!A15 -> 45323 | B16: ='Raw Data'!B15 -> Feb | C16: ='Raw Data'!C15 -> 2024 | D16: 11 | E16: ='Raw Data'!D15 -> 3041.5 | G16: ='Raw Data'!E15 -> 0 | H16: 4 | I16: ='Raw Data'!F15 -> 1106 | K16: ='Raw Data'!G15 -> 0 | O16: ='Raw Data'!H15 -> 0 | V16: =SUM(E16+G16+I16+K16+M16+O16) -> 4147.5 | Y16: =IFERROR((E16-E15)/E15,"") -> -0.35294118 | Z16: =IFERROR((G16-G15)/G15,"") | AA16: =IFERROR((I16-I15)/I15,"") -> 1 | AB16: =IFERROR((K16-K15)/K15,"") | AC16: =IFERROR((O16-O15)/O15,"") -> -1 | AD16: =IFERROR((V16-V15)/V15,"") -> -0.22454894
A17: ='Raw Data'!A16 -> 45352 | B17: ='Raw Data'!B16 -> Mar | C17: ='Raw Data'!C16 -> 2024 | D17: 9 | E17: ='Raw Data'!D16 -> 3038.5 | F17: 11 | G17: ='Raw Data'!E16 -> 3016.5 | I17: ='Raw Data'!F16 -> 0 | K17: ='Raw Data'!G16 -> 0 | N17: 68 | O17: ='Raw Data'!H16 -> 340 | V17: =SUM(E17+G17+I17+K17+M17+O17) -> 6395 | Y17: =IFERROR((E17-E16)/E16,"") -> -0.00098635542 | Z17: =IFERROR((G17-G16)/G16,"") | AA17: =IFERROR((I17-I16)/I16,"") -> -1 | AB17: =IFERROR((K17-K16)/K16,"") | AC17: =IFERROR((O17-O16)/O16,"") | AD17: =IFERROR((V17-V16)/V16,"") -> 0.54189271
A18: ='Raw Data'!A17 -> 45383 | B18: ='Raw Data'!B17 -> Apr | C18: ='Raw Data'!C17 -> 2024 | D18: 17 | E18: ='Raw Data'!D17 -> 4700.5 | F18: 11 | G18: ='Raw Data'!E17 -> 3041.5 | H18: 9 | I18: ='Raw Data'!F17 -> 2488.5 | K18: ='Raw Data'!G17 -> 0 | N18: 23 | O18: ='Raw Data'!H17 -> 115 | V18: =SUM(E18+G18+I18+K18+M18+O18) -> 10345.5 | Y18: =IFERROR((E18-E17)/E17,"") -> 0.54698042 | Z18: =IFERROR((G18-G17)/G17,"") -> 0.0082877507 | AA18: =IFERROR((I18-I17)/I17,"") | AB18: =IFERROR((K18-K17)/K17,"") | AC18: =IFERROR((O18-O17)/O17,"") -> -0.66176471 | AD18: =IFERROR((V18-V17)/V17,"") -> 0.61774824
A19: ='Raw Data'!A18 -> 45413 | B19: ='Raw Data'!B18 -> May | C19: ='Raw Data'!C18 -> 2024 | D19: 14 | E19: ='Raw Data'!D18 -> 3871 | G19: ='Raw Data'!E18 -> 0 | I19: ='Raw Data'!F18 -> 0 | K19: ='Raw Data'!G18 -> 0 | N19: 39 | O19: ='Raw Data'!H18 -> 195 | V19: =SUM(E19+G19+I19+K19+M19+O19) -> 4066 | Y19: =IFERROR((E19-E18)/E18,"") -> -0.17647059 | Z19: =IFERROR((G19-G18)/G18,"") -> -1 | AA19: =IFERROR((I19-I18)/I18,"") -> -1 | AB19: =IFERROR((K19-K18)/K18,"") | AC19: =IFERROR((O19-O18)/O18,"") -> 0.69565217 | AD19: =IFERROR((V19-V18)/V18,"") -> -0.60697888
A20: ='Raw Data'!A19 -> 45444 | B20: ='Raw Data'!B19 -> Jun | C20: ='Raw Data'!C19 -> 2024 | D20: 15 | E20: ='Raw Data'!D19 -> 4147.5 | F20: 12 | G20: ='Raw Data'!E19 -> 3318 | I20: ='Raw Data'!F19 -> 1935.5 | K20: ='Raw Data'!G19 -> 0 | N20: 69 | O20: ='Raw Data'!H19 -> 330 | V20: =SUM(E20+G20+I20+K20+M20+O20) -> 9731 | Y20: =IFERROR((E20-E19)/E19,"") -> 0.071428571 | Z20: =IFERROR((G20-G19)/G19,"") | AA20: =IFERROR((I20-I19)/I19,"") | AB20: =IFERROR((K20-K19)/K19,"") | AC20: =IFERROR((O20-O19)/O19,"") -> 0.69230769 | AD20: =IFERROR((V20-V19)/V19,"") -> 1.3932612
A21: ='Raw Data'!A20 -> 45474 | B21: ='Raw Data'!B20 -> Jul | C21: ='Raw Data'!C20 -> 2024 | D21: 9 | E21: ='Raw Data'!D20 -> 2488.5 | F21: 1 | G21: ='Raw Data'!E20 -> 275 | H21: 3 | I21: ='Raw Data'!F20 -> 829.5 | K21: ='Raw Data'!G20 -> 0 | N21: 40 | O21: ='Raw Data'!H20 -> 200 | V21: =SUM(E21+G21+I21+K21+M21+O21) -> 3793 | Y21: =IFERROR((E21-E20)/E20,"") -> -0.4 | Z21: =IFERROR((G21-G20)/G20,"") -> -0.91711875 | AA21: =IFERROR((I21-I20)/I20,"") -> -0.57142857 | AB21: =IFERROR((K21-K20)/K20,"") | AC21: =IFERROR((O21-O20)/O20,"") -> -0.39393939 | AD21: =IFERROR((V21-V20)/V20,"") -> -0.61021478
A22: ='Raw Data'!A21 -> 45505 | B22: ='Raw Data'!B21 -> Aug | C22: ='Raw Data'!C21 -> 2024 | D22: 11 | E22: ='Raw Data'!D21 -> 3041.5 | F22: 12 | G22: ='Raw Data'!E21 -> 3318 | H22: 2 | I22: ='Raw Data'!F21 -> 553 | J22: 15 | K22: ='Raw Data'!G21 -> 4143 | N22: 33 | O22: ='Raw Data'!H21 -> 165 | V22: =SUM(E22+G22+I22+K22+M22+O22) -> 11220.5 | Y22: =IFERROR((E22-E21)/E21,"") -> 0.22222222 | Z22: =IFERROR((G22-G21)/G21,"") -> 11.065455 | AA22: =IFERROR((I22-I21)/I21,"") -> -0.33333333 | AB22: =IFERROR((K22-K21)/K21,"") | AC22: =IFERROR((O22-O21)/O21,"") -> -0.175 | AD22: =IFERROR((V22-V21)/V21,"") -> 1.9582125
A23: ='Raw Data'!A22 -> 45536 | B23: ='Raw Data'!B22 -> Sep | C23: ='Raw Data'!C22 -> 2024 | D23: 6 | E23: ='Raw Data'!D22 -> 1659 | F23: 1 | G23: ='Raw Data'!E22 -> 275 | H23: 10 | I23: ='Raw Data'!F22 -> 2763.5 | K23: ='Raw Data'!G22 -> 0 | N23: 60 | O23: ='Raw Data'!H22 -> 300 | V23: =SUM(E23+G23+I23+K23+M23+O23) -> 4997.5 | Y23: =IFERROR((E23-E22)/E22,"") -> -0.45454545 | Z23: =IFERROR((G23-G22)/G22,"") -> -0.91711875 | AA23: =IFERROR((I23-I22)/I22,"") -> 3.9972875 | AB23: =IFERROR((K23-K22)/K22,"") -> -1 | AC23: =IFERROR((O23-O22)/O22,"") -> 0.81818182 | AD23: =IFERROR((V23-V22)/V22,"") -> -0.55460987
A24: ='Raw Data'!A23 -> 45566 | B24: ='Raw Data'!B23 -> Oct | C24: ='Raw Data'!C23 -> 2024 | E24: ='Raw Data'!D23 -> 0 | G24: ='Raw Data'!E23 -> 0 | I24: ='Raw Data'!F23 -> 0 | K24: ='Raw Data'!G23 -> 0 | N24: 27 | O24: ='Raw Data'!H23 -> 135 | V24: =SUM(E24+G24+I24+K24+M24+O24) -> 135 | Y24: =IFERROR((E24-E23)/E23,"") -> -1 | Z24: =IFERROR((G24-G23)/G23,"") -> -1 | AA24: =IFERROR((I24-I23)/I23,"") -> -1 | AB24: =IFERROR((K24-K23)/K23,"") | AC24: =IFERROR((O24-O23)/O23,"") -> -0.55 | AD24: =IFERROR((V24-V23)/V23,"") -> -0.97298649
A25: ='Raw Data'!A24 -> 45597 | B25: ='Raw Data'!B24 -> Nov | C25: ='Raw Data'!C24 -> 2024 | D25: 10 | E25: ='Raw Data'!D24 -> 2765 | G25: ='Raw Data'!E24 -> 0 | I25: ='Raw Data'!F24 -> 0 | J25: 12 | K25: ='Raw Data'!G24 -> 3318 | O25: ='Raw Data'!H24 -> 0 | V25: =SUM(E25+G25+I25+K25+M25+O25) -> 6083 | Y25: =IFERROR((E25-E24)/E24,"") | Z25: =IFERROR((G25-G24)/G24,"") | AA25: =IFERROR((I25-I24)/I24,"") | AB25: =IFERROR((K25-K24)/K24,"") | AC25: =IFERROR((O25-O24)/O24,"") -> -1 | AD25: =IFERROR((V25-V24)/V24,"") -> 44.059259
A26: ='Raw Data'!A25 -> 45627 | B26: ='Raw Data'!B25 -> Dec | C26: ='Raw Data'!C25 -> 2024 | D26: 12 | E26: ='Raw Data'!D25 -> 3191.5 | F26: 10 | G26: ='Raw Data'!E25 -> 2765 | H26: 6 | I26: ='Raw Data'!F25 -> 1659 | J26: 1 | K26: ='Raw Data'!G25 -> 275 | O26: ='Raw Data'!H25 -> 0 | V26: =SUM(E26+G26+I26+K26+M26+O26) -> 7890.5 | Y26: =IFERROR((E26-E25)/E25,"") -> 0.15424955 | Z26: =IFERROR((G26-G25)/G25,"") | AA26: =IFERROR((I26-I25)/I25,"") | AB26: =IFERROR((K26-K25)/K25,"") -> -0.91711875 | AC26: =IFERROR((O26-O25)/O25,"") | AD26: =IFERROR((V26-V25)/V25,"") -> 0.29713957
A27: ='Raw Data'!A26 -> 45658 | B27: ='Raw Data'!B26 -> Jan | C27: ='Raw Data'!C26 -> 2025 | D27: 12 | E27: ='Raw Data'!D26 -> 3040 | F27: -1 | G27: ='Raw Data'!E26 -> -276.5 | H27: 1 | I27: ='Raw Data'!F26 -> 0 | K27: ='Raw Data'!G26 -> 0 | O27: ='Raw Data'!H26 -> 0 | V27: =SUM(E27+G27+I27+K27+M27+O27) -> 2763.5 | W27: L3 2 tx & 1 refund; L2 1 refund | Y27: =IFERROR((E27-E26)/E26,"") -> -0.047469842 | Z27: =IFERROR((G27-G26)/G26,"") -> -1.1 | AA27: =IFERROR((I27-I26)/I26,"") -> -1 | AB27: =IFERROR((K27-K26)/K26,"") -> -1 | AC27: =IFERROR((O27-O26)/O26,"") | AD27: =IFERROR((V27-V26)/V26,"") -> -0.64976871
A28: ='Raw Data'!A27 -> 45689 | B28: ='Raw Data'!B27 -> Feb | C28: ='Raw Data'!C27 -> 2025 | D28: 14 | E28: ='Raw Data'!D27 -> 3871 | G28: ='Raw Data'!E27 -> 0 | I28: ='Raw Data'!F27 -> 0 | K28: ='Raw Data'!G27 -> 0 | N28: 71 | O28: ='Raw Data'!H27 -> 355 | V28: =SUM(E28+G28+I28+K28+M28+O28) -> 4226 | Y28: =IFERROR((E28-E27)/E27,"") -> 0.27335526 | Z28: =IFERROR((G28-G27)/G27,"") -> -1 | AA28: =IFERROR((I28-I27)/I27,"") | AB28: =IFERROR((K28-K27)/K27,"") | AC28: =IFERROR((O28-O27)/O27,"") | AD28: =IFERROR((V28-V27)/V27,"") -> 0.52922019
A29: ='Raw Data'!A28 -> 45717 | B29: ='Raw Data'!B28 -> Mar | C29: ='Raw Data'!C28 -> 2025 | D29: 6 | E29: ='Raw Data'!D28 -> 1659 | F29: 6 | G29: ='Raw Data'!E28 -> 1659 | H29: 11 | I29: ='Raw Data'!F28 -> 3041.5 | K29: ='Raw Data'!G28 -> 0 | N29: 65 | O29: ='Raw Data'!H28 -> 320 | V29: =SUM(E29+G29+I29+K29+M29+O29) -> 6679.5 | Y29: =IFERROR((E29-E28)/E28,"") -> -0.57142857 | Z29: =IFERROR((G29-G28)/G28,"") | AA29: =IFERROR((I29-I28)/I28,"") | AB29: =IFERROR((K29-K28)/K28,"") | AC29: =IFERROR((O29-O28)/O28,"") -> -0.098591549 | AD29: =IFERROR((V29-V28)/V28,"") -> 0.58057265
A30: ='Raw Data'!A29 -> 45748 | B30: ='Raw Data'!B29 -> Apr | C30: ='Raw Data'!C29 -> 2025 | D30: 4 | E30: ='Raw Data'!D29 -> 1106 | F30: -3 | G30: ='Raw Data'!E29 -> -829.5 | H30: 1 | I30: ='Raw Data'!F29 -> 275 | K30: ='Raw Data'!G29 -> 0 | N30: 38 | O30: ='Raw Data'!H29 -> 190 | V30: =SUM(E30+G30+I30+K30+M30+O30) -> 741.5 | W30: L3 3 refunds | Y30: =IFERROR((E30-E29)/E29,"") -> -0.33333333 | Z30: =IFERROR((G30-G29)/G29,"") -> -1.5 | AA30: =IFERROR((I30-I29)/I29,"") -> -0.90958409 | AB30: =IFERROR((K30-K29)/K29,"") | AC30: =IFERROR((O30-O29)/O29,"") -> -0.40625 | AD30: =IFERROR((V30-V29)/V29,"") -> -0.8889887
A31: ='Raw Data'!A30 -> 45778 | B31: ='Raw Data'!B30 -> May | C31: ='Raw Data'!C30 -> 2025 | D31: 13 | E31: ='Raw Data'!D30 -> 3594.5 | F31: 2 | G31: ='Raw Data'!E30 -> 276.5 | I31: ='Raw Data'!F30 -> 0 | K31: ='Raw Data'!G30 -> 0 | O31: ='Raw Data'!H30 -> 0 | V31: =SUM(E31+G31+I31+K31+M31+O31) -> 3871 | Y31: =IFERROR((E31-E30)/E30,"") -> 2.25 | Z31: =IFERROR((G31-G30)/G30,"") -> -1.3333333 | AA31: =IFERROR((I31-I30)/I30,"") -> -1 | AB31: =IFERROR((K31-K30)/K30,"") | AC31: =IFERROR((O31-O30)/O30,"") -> -1 | AD31: =IFERROR((V31-V30)/V30,"") -> 4.220499
A32: ='Raw Data'!A31 -> 45809 | B32: ='Raw Data'!B31 -> Jun | C32: ='Raw Data'!C31 -> 2025 | D32: 6 | E32: ='Raw Data'!D31 -> 1659 | F32: 7 | G32: ='Raw Data'!E31 -> 1935.5 | I32: ='Raw Data'!F31 -> 0 | K32: ='Raw Data'!G31 -> 0 | N32: 42 | O32: ='Raw Data'!H31 -> 210 | V32: =SUM(E32+G32+I32+K32+M32+O32) -> 3804.5 | Y32: =IFERROR((E32-E31)/E31,"") -> -0.53846154 | Z32: =IFERROR((G32-G31)/G31,"") -> 6 | AA32: =IFERROR((I32-I31)/I31,"") | AB32: =IFERROR((K32-K31)/K31,"") | AC32: =IFERROR((O32-O31)/O31,"") | AD32: =IFERROR((V32-V31)/V31,"") -> -0.017179024
A33: ='Raw Data'!A32 -> 45839 | B33: ='Raw Data'!B32 -> Jul | C33: ='Raw Data'!C32 -> 2025 | D33: 15 | E33: ='Raw Data'!D32 -> 4147.5 | F33: 8 | G33: ='Raw Data'!E32 -> 2212 | H33: 1 | I33: ='Raw Data'!F32 -> 276.5 | J33: 12 | K33: ='Raw Data'!G32 -> 3041.5 | N33: 15 | O33: ='Raw Data'!H32 -> 75 | V33: =SUM(E33+G33+I33+K33+M33+O33) -> 9752.5 | Y33: =IFERROR((E33-E32)/E32,"") -> 1.5 | Z33: =IFERROR((G33-G32)/G32,"") -> 0.14285714 | AA33: =IFERROR((I33-I32)/I32,"") | AB33: =IFERROR((K33-K32)/K32,"") | AC33: =IFERROR((O33-O32)/O32,"") -> -0.64285714 | AD33: =IFERROR((V33-V32)/V32,"") -> 1.5634117
A34: ='Raw Data'!A33 -> 45870 | B34: ='Raw Data'!B33 -> Aug | C34: ='Raw Data'!C33 -> 2025 | D34: 13 | E34: ='Raw Data'!D33 -> 3594.5 | F34: 2 | G34: ='Raw Data'!E33 -> 551.5 | H34: 1 | I34: ='Raw Data'!F33 -> 276.5 | K34: ='Raw Data'!G33 -> 0 | N34: 27 | O34: ='Raw Data'!H33 -> 135 | V34: =SUM(E34+G34+I34+K34+M34+O34) -> 4557.5 | Y34: =IFERROR((E34-E33)/E33,"") -> -0.13333333 | Z34: =IFERROR((G34-G33)/G33,"") -> -0.75067812 | AA34: =IFERROR((I34-I33)/I33,"") -> 0 | AB34: =IFERROR((K34-K33)/K33,"") -> -1 | AC34: =IFERROR((O34-O33)/O33,"") -> 0.8 | AD34: =IFERROR((V34-V33)/V33,"") -> -0.53268393
A35: ='Raw Data'!A34 -> 45901 | B35: ='Raw Data'!B34 -> Sep | C35: ='Raw Data'!C34 -> 2025 | D35: 13 | E35: ='Raw Data'!D34 -> 3593 | F35: 9 | G35: ='Raw Data'!E34 -> 2488.5 | H35: 3 | I35: ='Raw Data'!F34 -> 828 | K35: ='Raw Data'!G34 -> 0 | N35: 33 | O35: ='Raw Data'!H34 -> 165 | V35: =SUM(E35+G35+I35+K35+M35+O35) -> 7074.5 | Y35: =IFERROR((E35-E34)/E34,"") -> -0.00041730421 | Z35: =IFERROR((G35-G34)/G34,"") -> 3.5122393 | AA35: =IFERROR((I35-I34)/I34,"") -> 1.994575 | AB35: =IFERROR((K35-K34)/K34,"") | AC35: =IFERROR((O35-O34)/O34,"") -> 0.22222222 | AD35: =IFERROR((V35-V34)/V34,"") -> 0.55227647
A36: ='Raw Data'!A35 -> 45931 | B36: ='Raw Data'!B35 -> Oct | C36: ='Raw Data'!C35 -> 2025 | D36: 11 | E36: ='Raw Data'!D35 -> 3038.5 | G36: ='Raw Data'!E35 -> 0 | H36: 6 | I36: ='Raw Data'!F35 -> 1659 | K36: ='Raw Data'!G35 -> 0 | N36: 99 | O36: ='Raw Data'!H35 -> 495 | V36: =SUM(E36+G36+I36+K36+M36+O36) -> 5192.5 | Y36: =IFERROR((E36-E35)/E35,"") -> -0.15432786 | Z36: =IFERROR((G36-G35)/G35,"") -> -1 | AA36: =IFERROR((I36-I35)/I35,"") -> 1.0036232 | AB36: =IFERROR((K36-K35)/K35,"") | AC36: =IFERROR((O36-O35)/O35,"") -> 2 | AD36: =IFERROR((V36-V35)/V35,"") -> -0.26602587
A37: ='Raw Data'!A36 -> 45962 | B37: ='Raw Data'!B36 -> Nov | C37: ='Raw Data'!C36 -> 2025 | D37: 9 | E37: 2284 | F37: 7 | G37: 1725 | H37: 2 | I37: 601 | K37: ='Raw Data'!G36 -> 0 | N37: 37 | O37: 185 | V37: =SUM(E37+G37+I37+K37+M37+O37) -> 4795 | Y37: =IFERROR((E37-E36)/E36,"") -> -0.24831331 | Z37: =IFERROR((G37-G36)/G36,"") | AA37: =IFERROR((I37-I36)/I36,"") -> -0.63773357 | AB37: =IFERROR((K37-K36)/K36,"") | AC37: =IFERROR((O37-O36)/O36,"") -> -0.62626263 | AD37: =IFERROR((V37-V36)/V36,"") -> -0.07655272
A38: ='Raw Data'!A37 -> 45992 | B38: ='Raw Data'!B37 -> Dec | C38: ='Raw Data'!C37 -> 2025 | D38: 8 | E38: 2404 | F38: 9 | G38: 2712.5 | H38: 3 | I38: 901.5 | J38: 3 | K38: 901.5 | L38: 17 | M38: 566.5 | N38: 54 | O38: 270 | V38: =SUM(E38+G38+I38+K38+M38+O38) -> 7756 | Y38: =IFERROR((E38-E37)/E37,"") -> 0.052539405 | Z38: =IFERROR((G38-G37)/G37,"") -> 0.57246377 | AA38: =IFERROR((I38-I37)/I37,"") -> 0.5 | AB38: =IFERROR((K38-K37)/K37,"") | AC38: =IFERROR((O38-O37)/O37,"") -> 0.45945946 | AD38: =IFERROR((V38-V37)/V37,"") -> 0.61751825
A39: 46023 | B39: Jan | C39: 2026 | D39: 14 | E39: 4207.5 | F39: 13 | G39: 3055.5 | H39: 4 | I39: 1202 | J39: -1 | K39: -300.5 | L39: 39 | M39: 2368.5 | N39: 22 | O39: 110 | P39: 7 | Q39: 1585.5 | R39: 12 | S39: 618 | T39: 70 | U39: 3884 | V39: =SUM(E39+G39+I39+K39+M39+O39+Q39+S39+U39) -> 16730.5
A40: 46054 | B40: Feb | C40: 2026 | K40: ='Raw Data'!G39 -> 0 | V40: =SUM(E40+G40+I40+K40+M40+O40) -> 0
...

Sheet Raw Data
A1: Date | B1: Month | C1: Year | D1: Level 1 | E1: Level 2 | F1: Level 3 | G1: Level 4 | H1: HIS Showcase | I1: CSz | J1: CSZ GFT Grand Opening | K1: Beer Babies | L1: Improv the Musical | M1: Maestro | N1: Bards Bounty | O1: Schooby-Doo | P1: Charlie BrownChristmas | Q1: Newest Olypian | R1: May the 4th Be With You | S1: Chris Grace & Tim Murry Stand Up | T1: Improv Rodeo | U1: Merch | V1: other | W1: Total
A2: 44927 | B2: =TEXT(A2,"mmm") -> Jan | C2: =YEAR(A2) -> 2023 | D2: 5253.5 | E2: 3318 | F2: 829.5 | H2: 275 | I2: 5642 | K2: 1009 | T2: 1716.5 | W2: =SUM(D2:V2) -> 18043.5
A3: 44958 | B3: =TEXT(A3,"mmm") -> Feb | C3: =YEAR(A3) -> 2023 | D3: 2765 | I3: 6743 | K3: 627.5 | T3: 220.5 | U3: 44 | W3: =SUM(D3:V3) -> 10400
A4: 44986 | B4: =TEXT(A4,"mmm") -> Mar | C4: =YEAR(A4) -> 2023 | D4: 4424 | E4: 3595 | G4: 1106 | H4: 425 | I4: 5878 | K4: 490 | N4: 93 | S4: 53 | W4: =SUM(D4:V4) -> 16064
A5: 45017 | B5: =TEXT(A5,"mmm") -> Apr | C5: =YEAR(A5) -> 2023 | D5: 2212 | F5: 0 | G5: -829.5 | H5: 110 | I5: 4186.5 | K5: 418.5 | N5: 684.5 | R5: 31 | S5: 631.5 | W5: =SUM(D5:V5) -> 7444.5
A6: 45047 | B6: =TEXT(A6,"mmm") -> May | C6: =YEAR(A6) -> 2023 | D6: 3318 | E6: 3494.5 | H6: 250 | I6: 4997.5 | K6: 220 | N6: 772.5 | R6: 344 | W6: =SUM(D6:V6) -> 13396.5
A7: 45078 | B7: =TEXT(A7,"mmm") -> Jun | C7: =YEAR(A7) -> 2023 | D7: 2212 | F7: 276.5 | H7: 70 | I7: 6412 | K7: 0 | N7: 481.5 | U7: 14 | W7: =SUM(D7:V7) -> 9466
A8: 45108 | B8: =TEXT(A8,"mmm") -> Jul | C8: =YEAR(A8) -> 2023 | D8: 1935.5 | E8: 2212 | F8: 1106 | H8: 90 | I8: 5599 | K8: 393.5 | N8: 608 | U8: 885.8 | W8: =SUM(D8:V8) -> 12829.8
A9: 45139 | B9: =TEXT(A9,"mmm") -> Aug | C9: =YEAR(A9) -> 2023 | D9: 4146 | E9: 1106 | F9: 829.5 | I9: 5097.5 | K9: 401 | N9: 403.5 | W9: =SUM(D9:V9) -> 11983.5
A10: 45170 | B10: =TEXT(A10,"mmm") -> Sep | C10: =YEAR(A10) -> 2023 | D10: 3040 | E10: 829 | H10: 65 | I10: 6238.5 | K10: 455.5 | L10: 35 | N10: 299.5 | Q10: 946 | U10: 68 | W10: =SUM(D10:V10) -> 11976.5
A11: 45200 | B11: =TEXT(A11,"mmm") -> Oct | C11: =YEAR(A11) -> 2023 | D11: 2488.5 | E11: 1382.5 | F11: 276.5 | G11: 829.5 | H11: 315 | I11: 4042.5 | K11: 558 | L11: 258 | N11: 614.5 | O11: 640 | Q11: 215 | U11: 50 | W11: =SUM(D11:V11) -> 11670
A12: 45231 | B12: =TEXT(A12,"mmm") -> Nov | C12: =YEAR(A12) -> 2023 | D12: 2488.5 | F12: 829.5 | G12: 829.5 | H12: 120 | I12: 6908.5 | K12: 341 | L12: 337.5 | N12: 203 | Q12: 172 | U12: 75 | W12: =SUM(D12:V12) -> 12304.5
A13: 45261 | B13: =TEXT(A13,"mmm") -> Dec | C13: =YEAR(A13) -> 2023 | D13: 3041.5 | E13: 3593 | H13: 105 | I13: 5489 | K13: 403 | L13: 97 | N13: 284 | P13: 432 | Q13: 559 | U13: 120 | W13: =SUM(D13:V13) -> 14123.5
A14: 45292 | B14: =TEXT(A14,"mmm") -> Jan | C14: =YEAR(A14) -> 2024 | D14: 4700.5 | E14: 0 | F14: 553 | H14: 95 | I14: 6265.5 | K14: 140 | L14: 566 | N14: 495 | W14: =SUM(D14:V14) -> 12815
A15: 45323 | B15: =TEXT(A15,"mmm") -> Feb | C15: =YEAR(A15) -> 2024 | D15: 3041.5 | F15: 1106 | I15: 6405 | K15: 463 | L15: 631 | U15: 124 | W15: =SUM(D15:V15) -> 11770.5
A16: 45352 | B16: =TEXT(A16,"mmm") -> Mar | C16: =YEAR(A16) -> 2024 | D16: 3038.5 | E16: 3016.5 | H16: 340 | I16: 5414.5 | K16: 376 | L16: 601 | N16: 427 | U16: 84 | W16: =SUM(D16:V16) -> 13297.5
A17: 45383 | B17: =TEXT(A17,"mmm") -> Apr | C17: =YEAR(A17) -> 2024 | D17: 4700.5 | E17: 3041.5 | F17: 2488.5 | H17: 115 | I17: 3939 | K17: 375 | L17: 337.5 | N17: 425.5 | U17: 80 | W17: =SUM(D17:V17) -> 15502.5
A18: 45413 | B18: =TEXT(A18,"mmm") -> May | C18: =YEAR(A18) -> 2024 | D18: 3871 | H18: 195 | I18: 4337.5 | K18: 159.5 | L18: 521.5 | M18: 77.5 | N18: 586.5 | U18: 355 | W18: =SUM(D18:V18) -> 10103.5
A19: 45444 | B19: =TEXT(A19,"mmm") -> Jun | C19: =YEAR(A19) -> 2024 | D19: 4147.5 | E19: 3318 | F19: 1935.5 | H19: 330 | I19: 5022 | K19: 361.5 | L19: 177 | M19: 292 | N19: 459.5 | U19: 40 | W19: =SUM(D19:V19) -> 16083
A20: 45474 | B20: =TEXT(A20,"mmm") -> Jul | C20: =YEAR(A20) -> 2024 | D20: 2488.5 | E20: 275 | F20: 829.5 | H20: 200 | I20: 4500 | K20: -70 | L20: 309 | M20: 241 | N20: 718.5 | U20: 50 | W20: =SUM(D20:V20) -> 9541.5
A21: 45505 | B21: =TEXT(A21,"mmm") -> Aug | C21: =YEAR(A21) -> 2024 | D21: 3041.5 | E21: 3318 | F21: 553 | G21: 4143 | H21: 165 | I21: 4604.5 | K21: 354 | L21: 93 | M21: 57.5 | N21: 397.5 | W21: =SUM(D21:V21) -> 16727
A22: 45536 | B22: =TEXT(A22,"mmm") -> Sep | C22: =YEAR(A22) -> 2024 | D22: 1659 | E22: 275 | F22: 2763.5 | H22: 300 | I22: 3372.5 | K22: 766.5 | L22: 205 | M22: 370 | N22: 479 | W22: =SUM(D22:V22) -> 10190.5
A23: 45566 | B23: =TEXT(A23,"mmm") -> Oct | C23: =YEAR(A23) -> 2024 | H23: 135 | I23: 2611 | K23: 140 | L23: 224.5 | M23: 31 | N23: 291 | O23: 310 | W23: =SUM(D23:V23) -> 3742.5
A24: 45597 | B24: =TEXT(A24,"mmm") -> Nov | C24: =YEAR(A24) -> 2024 | D24: 2765 | G24: 3318 | I24: 3449.5 | K24: 209 | M24: 360.5 | N24: 485 | U24: 40 | W24: =SUM(D24:V24) -> 10627
A25: 45627 | B25: =TEXT(A25,"mmm") -> Dec | C25: =YEAR(A25) -> 2024 | D25: 3191.5 | E25: 2765 | F25: 1659 | G25: 275 | I25: 4777.5 | K25: 207 | L25: 76 | M25: 337 | N25: 341.5 | U25: 540 | W25: =SUM(D25:V25) -> 14169.5
A26: 45658 | B26: =TEXT(A26,"mmm") -> Jan | C26: =YEAR(A26) -> 2025 | D26: 3040 | E26: -276.5 | F26: 0 | I26: 6464 | K26: 857.5 | L26: 342 | M26: 124 | N26: 544.5 | U26: 4 | W26: =SUM(D26:V26) -> 11099.5
A27: 45689 | B27: =TEXT(A27,"mmm") -> Feb | C27: =YEAR(A27) -> 2025 | D27: 3871 | H27: 355 | I27: 3966.5 | K27: 331.5 | L27: 344 | M27: 217 | N27: 377 | W27: =SUM(D27:V27) -> 9462
A28: 45717 | B28: =TEXT(A28,"mmm") -> Mar | C28: =YEAR(A28) -> 2025 | D28: 1659 | E28: 1659 | F28: 3041.5 | H28: 320 | I28: 3948.5 | K28: 294.5 | L28: 180 | M28: 379 | N28: 437.5 | U28: 5 | W28: =SUM(D28:V28) -> 11924
A29: 45748 | B29: =TEXT(A29,"mmm") -> Apr | C29: =YEAR(A29) -> 2025 | D29: 1106 | E29: -829.5 | F29: 275 | H29: 190 | I29: 3198 | K29: 374.5 | L29: 259.5 | N29: 519.5 | W29: =SUM(D29:V29) -> 5093
A30: 45778 | B30: =TEXT(A30,"mmm") -> May | C30: =YEAR(A30) -> 2025 | D30: 3594.5 | E30: 276.5 | I30: 3765.5 | K30: 144 | L30: 254.5 | N30: 473 | U30: 21.5 | W30: =SUM(D30:V30) -> 8529.5
A31: 45809 | B31: =TEXT(A31,"mmm") -> Jun | C31: =YEAR(A31) -> 2025 | D31: 1659 | E31: 1935.5 | H31: 210 | I31: 3761.5 | K31: 484.5 | L31: 269.5 | M31: 393 | N31: 415.5 | V31: 2 | W31: =SUM(D31:V31) -> 9130.5
A32: 45839 | B32: =TEXT(A32,"mmm") -> Jul | C32: =YEAR(A32) -> 2025 | D32: 4147.5 | E32: 2212 | F32: 276.5 | G32: 3041.5 | H32: 75 | I32: 2845 | J32: 2117 | V32: 4 | W32: =SUM(D32:V32) -> 14718.5
A33: 45870 | B33: =TEXT(A33,"mmm") -> Aug | C33: =YEAR(A33) -> 2025 | D33: 3594.5 | E33: 551.5 | F33: 276.5 | H33: 135 | I33: 7514.5 | N33: 445 | W33: =SUM(D33:V33) -> 12517
A34: 45901 | B34: =TEXT(A34,"mmm") -> Sep | C34: =YEAR(A34) -> 2025 | D34: 3593 | E34: 2488.5 | F34: 828 | H34: 165 | I34: 6315 | N34: 658 | W34: =SUM(D34:V34) -> 14047.5
A35: 45931 | B35: =TEXT(A35,"mmm") -> Oct | C35: =YEAR(A35) -> 2025 | D35: 3038.5 | F35: 1659 | H35: 495 | I35: 4188.5 | N35: 329.5 | W35: =SUM(D35:V35) -> 9710.5
A36: 45962 | B36: =TEXT(A36,"mmm") -> Nov | C36: =YEAR(A36) -> 2025
A37: 45992 | B37: =TEXT(A37,"mmm") -> Dec | C37: =YEAR(A37) -> 2025
